<?xml version="1.0"?>
<robot xmlns:xacro="http://ros.org/wiki/xacro">
  <xacro:macro name="wheel" params="side radius width pos_x pos_y pos_z mass rim_mesh wheel_mesh scale">
    <link name="${side}_rim_link">
      <visual>
        <origin xyz="0 0 0" rpy="0 0 0"/>
        <geometry>
          <mesh filename="${rim_mesh}" scale="${scale} ${scale} ${scale}"/>
        </geometry>
        <material name="blue">
            <color rgba="0.1764 0.4588 0.8509 1.0"/>
        </material>
      </visual>
      <collision>
        <origin xyz="0 0 0" rpy="${pi/2} 0 0"/>
        <geometry>
          <cylinder radius="${radius}" length="${width}"/>
        </geometry>
      </collision>

      <inertial>
        <origin xyz="0 0 0" rpy="0 0 0"/>
        <mass value="${mass}"/>
        <inertia ixx="${(2/5) * mass * (radius * radius)}" ixy="0" ixz="0"
                 iyy="${(2/5) * mass * (radius * radius)}" iyz="0"
                 izz="${(2/5) * mass * (radius * radius)}" />
      </inertial>
    </link>

    <link name="${side}_wheel_link">
      <visual>
        <origin xyz="0 0 0" rpy="0 0 0"/>
        <geometry>
          <mesh filename="${wheel_mesh}" scale="${scale} ${scale} ${scale}"/>
        </geometry>
        <material name="blue">
            <color rgba="0.1764 0.4588 0.8509 1.0"/>
        </material>
      </visual>
      <collision>
        <origin xyz="0 0 0" rpy="${pi/2} 0 0"/>
        <geometry>
          <cylinder radius="${radius}" length="${width}"/>
        </geometry>
      </collision>

      <inertial>
        <origin xyz="0 0 0" rpy="0 0 0"/>
        <mass value="${mass}"/>
        <inertia ixx="${(2/5) * mass * (radius * radius)}" ixy="0" ixz="0"
                 iyy="${(2/5) * mass * (radius * radius)}" iyz="0"
                 izz="${(2/5) * mass * (radius * radius)}" />
      </inertial>
    </link>

    <gazebo reference="${side}_wheel_link">  
      <material>Gazebo/FlatBlack</material>
    </gazebo>

    <gazebo reference="${side}_rim_link">  
      <material>Gazebo/White</material>
    </gazebo>

    <joint name="${side}_wheel_joint" type="continuous">
      <axis xyz="0 1 0" />
      <parent link="base_link"/>
      <child link="${side}_wheel_link"/>
      <origin xyz="${pos_x} ${pos_y} ${pos_z}" rpy="0 0 0"/>
    </joint>

    <joint name="${side}_rim_joint" type="fixed">
      <axis xyz="0 1 0" />
      <parent link="${side}_wheel_link"/>
      <child link="${side}_rim_link"/>
      <origin xyz="0 0 0" rpy="0 0 0"/>
    </joint>
  </xacro:macro>
</robot>